<robot name="rotary_inverted_pendulum">

    <material name="grey">
        <color rgba="0.7 0.7 0.7 1"/>
    </material>

    <material name="green">
        <color rgba="0 0.6 0 1"/>
    </material>

    <material name="red">
        <color rgba="1 0 0 1"/>
    </material>

    <link name="base_link">
        <visual>
            <geometry>
                <cylinder radius="0.05" length="0.3"/>
            </geometry>
            <origin xyz="0 0 0.15" rpy="0 0 0"/>
            <material name="green"/>
        </visual>
    </link>

    <link name="arm_link">
        <visual>
            <geometry>
                <box size="0.06 0.03 0.01"/>
            </geometry>
            <origin xyz="0.03 0 0" rpy="0 0 0"/>
            <material name="grey"/>
        </visual>
    </link>

    <link name="pendulum_link">
        <visual>
            <geometry>
                <box size="0.2 0.03 0.01"/>
            </geometry>
            <origin xyz="0.1  0 0" rpy="0 0 0"/>
            <material name="red"/>
        </visual>
    </link>

    <joint name="base_arm_joint" type="revolute">
        <parent link="base_link"/>
        <child link="arm_link"/>
        <origin xyz="0 0 0.30" rpy="0 0 0"/>
        <axis xyz="0 0 1"/> 
        <limit effort="10" lower="-3.1416" upper="3.1416" velocity="1.0"/>
    </joint>  

    <joint name="arm_pendulum_joint" type="revolute">
        <parent link="arm_link"/> 
        <child link="pendulum_link"/>
        <origin xyz="0.06 0 0" rpy="0 1.5708 0"/> 
        <axis xyz="0 0 1"/> 
        <limit effort="10" lower="-3.1416" upper="3.1416" velocity="1.0"/>
    </joint>
</robot>
